Workbook

Sheet Live data
A1: id | B1: code | C1: station | D1: latitude | E1: longitude | F1: services | G1: openTime | H1: closeTime | I1: phone Number
A2: 0 | B2: #RH-KE-NBI-A-01 | C2: Lusaka Road - TotalEnergies | D2: -1.3011345 | E2: 36.832905 | F2: Battery charging, Battery Rental | G2: 7:00 AM | H2: 7:00PM | I2: 254111917217
A3: 1 | B3: #RH-KE-NBI-A-02 | C3: Wayaki Way - TotalEnergies | D3: -1.2579405 | E3: 36.781329 | F3: Battery charging, Battery Rental | G3: 7:00 AM | H3: 7:00PM | I3: 254113585123
A4: 2 | B4: #RH-KE-NBI-A-03 | C4: Ngong Road - TotalEnergies | D4: -1.2996674 | E4: 36.788717 | F4: Battery charging, Battery Rental | G4: 7:00 AM | H4: 7:00PM
A5: 3 | B5: #RP-KE-NBI-A-04 | C5: Jogoo Road - M-KOPA Shell | D5: -1.292109 | E5: 36.843321 | F5: Battery Rental | G5: 8:00 AM | H5: 5:00 PM
A6: 4 | B6: #RP-KE-NBI-A-05 | C6: Lavington - M-KOPA Shell | D6: -1.279364 | E6: 36.770414 | F6: Battery Rental | G6: 8:00 AM | H6: 5:00 PM
A7: 5 | B7: #RP-KE-NBI-A-06 | C7: Kawangware - M-KOPA Shell | D7: -1.287923 | E7: 36.741585 | F7: Battery Rental | G7: 8:00 AM | H7: 5:00 PM
A8: 6 | B8: #RH-KE-NBI-A-07 | C8: South C - TotalEnergies | F8: Battery charging | G8: Open 24hrs | H8: Open 24hrs
A9: 7 | B9: #RH-KE-NBI-A-08 | C9: Outer Ring - TotalEnergies | F9: Battery charging | G9: Open 24hrs | H9: Open 24hrs
A10: 8 | B10: #RH-KE-NBI-A-09 | C10: TotalEnergies - Ruaraka | D10: -1.227694 | E10: 36.883355 | F10: Battery charging | G10: Open 24hrs | H10: Open 24hrs
A11: 9 | B11: #RH-KE-NBI-A-10 | C11: Coming Soon: Regen | D11: -1.2548636 | E11: 36.663139 | F11: Battery charging | G11: Open 24hrs | H11: Open 24hrs
A12: 10 | B12: #RH-KE-NBI-A-11 | C12: Coming Soon: Eastleigh | D12: -1.268001 | E12: 36.84817 | F12: Battery charging | G12: Open 24hrs | H12: Open 24hrs
A13: 11 | B13: #RH-KE-NBI-A-12 | C13: Coming Soon: Adlife | D13: -1.29483 | E13: 36.78731 | F13: Battery charging | G13: Open 24hrs | H13: Open 24hrs

Sheet RK - KE - NBI
I1: =countif(I3:I1001,"Operational") -> 3 | J1: Site Information | O1: Site Manager | T1: Extinguishers | U1: Rom Hubs | V1: Number of Chargers | Y1: Services
A2: Short Name | B2: Long Name | C2: Country | D2: County | E2: Alphabet | F2: No | G2: Roam Charger ID | H2: Dynamics Project Code | I2: Status | J2: Partner | K2: Site Name | L2: Charger Name | M2: Complete Name | N2: Coordinate | O2: Full Name | P2: Phone Number | Q2: Ownership | R2: Operation | S2: Release | T2: Next Date of Control | U2: Phone Number | V2: 10A | W2: 20A | X2: 30A | Y2: Charging | Z2: Rental
A3: RK | B3: =vlookup(A3,'List of Chargers'!$A$2:$B$5,2,FALSE) -> Roam Kiosk | C3: KE | D3: NBI | E3: A | F3: 01 | G3: =CONCATENATE("#",A3,"-",C3,"-",D3,"-",E3,"-",F3,) -> #RK-KE-NBI-A-01 | H3: =concatenate(G3) -> #RK-KE-NBI-A-01 | I3: Operational | J3: M-KOPA | K3: Shell Jogoo Road | L3: =B3&" - "&K3 -> Roam Kiosk - Shell Jogoo Road | M3: =CONCATENATE(G3," - Rental Kiosk - ",J3," - ",K3) -> #RK-KE-NBI-A-01 - Rental Kiosk - M-KOPA - Shell Jogoo Road | Q3: Roam Electric Limited | R3: Mkopa Kenya | S3: Mombasa | V3: 4 | W3: 0 | X3: 0 | Y3: FALSE | Z3: TRUE
A4: RK | B4: =vlookup(A4,'List of Chargers'!$A$2:$B$5,2,FALSE) -> Roam Kiosk | C4: KE | D4: NBI | E4: A | F4: 02 | G4: =CONCATENATE("#",A4,"-",C4,"-",D4,"-",E4,"-",F4,) -> #RK-KE-NBI-A-02 | H4: =concatenate(G4) -> #RK-KE-NBI-A-02 | I4: Operational | J4: M-KOPA | K4: Shell Lavington | L4: =B4&" - "&K4 -> Roam Kiosk - Shell Lavington | M4: =CONCATENATE(G4," - Rental Kiosk - ",J4," - ",K4) -> #RK-KE-NBI-A-02 - Rental Kiosk - M-KOPA - Shell Lavington | Q4: Roam Electric Limited | R4: Mkopa Kenya | S4: Mombasa | V4: 4 | W4: 0 | X4: 0 | Y4: FALSE | Z4: TRUE
A5: RK | B5: =vlookup(A5,'List of Chargers'!$A$2:$B$5,2,FALSE) -> Roam Kiosk | C5: KE | D5: NBI | E5: A | F5: 03 | G5: =CONCATENATE("#",A5,"-",C5,"-",D5,"-",E5,"-",F5,) -> #RK-KE-NBI-A-03 | H5: =concatenate(G5) -> #RK-KE-NBI-A-03 | I5: Operational | J5: M-KOPA | K5: Shell Kawangware | L5: =B5&" - "&K5 -> Roam Kiosk - Shell Kawangware | M5: =CONCATENATE(G5," - Rental Kiosk - ",J5," - ",K5) -> #RK-KE-NBI-A-03 - Rental Kiosk - M-KOPA - Shell Kawangware | Q5: Roam Electric Limited | R5: Mkopa Kenya | S5: Mombasa | V5: 4 | W5: 0 | X5: 0 | Y5: FALSE | Z5: TRUE
A6: RK | B6: =vlookup(A6,'List of Chargers'!$A$2:$B$5,2,FALSE) -> Roam Kiosk | C6: KE | D6: NBI | E6: A | F6: 04 | G6: =CONCATENATE("#",A6,"-",C6,"-",D6,"-",E6,"-",F6,) -> #RK-KE-NBI-A-04 | H6: =concatenate(G6) -> #RK-KE-NBI-A-04 | I6: Construction | J6: RideWell | K6: TotalEnergies Ruaraka | L6: =B6&" - "&K6 -> Roam Kiosk - TotalEnergies Ruaraka | M6: =CONCATENATE(G6," - Rental Kiosk - ",J6," - ",K6) -> #RK-KE-NBI-A-04 - Rental Kiosk - RideWell - TotalEnergies Ruaraka | Y6: FALSE | Z6: FALSE
A7: RK | B7: =vlookup(A7,'List of Chargers'!$A$2:$B$5,2,FALSE) -> Roam Kiosk | C7: KE | D7: NBI | E7: A | F7: 05 | G7: =CONCATENATE("#",A7,"-",C7,"-",D7,"-",E7,"-",F7,) -> #RK-KE-NBI-A-05 | H7: =concatenate(G7) -> #RK-KE-NBI-A-05 | I7: Blocked | J7: Mogo | K7: ?? | L7: =B7&" - "&K7 -> Roam Kiosk - ?? | M7: =CONCATENATE(G7," - Rental Kiosk - ",J7," - ",K7) -> #RK-KE-NBI-A-05 - Rental Kiosk - Mogo - ?? | Y7: FALSE | Z7: FALSE
A8: RK | B8: =vlookup(A8,'List of Chargers'!$A$2:$B$5,2,FALSE) -> Roam Kiosk | C8: KE | D8: NBI | E8: A | F8: 06 | G8: =CONCATENATE("#",A8,"-",C8,"-",D8,"-",E8,"-",F8,) -> #RK-KE-NBI-A-06 | H8: =concatenate(G8) -> #RK-KE-NBI-A-06 | L8: =B8&" - "&K8 -> Roam Kiosk - | M8: =CONCATENATE(G8," - Rental Kiosk - ",J8," - ",K8) -> #RK-KE-NBI-A-06 - Rental Kiosk - - | Y8: FALSE | Z8: FALSE
A9: RK | B9: =vlookup(A9,'List of Chargers'!$A$2:$B$5,2,FALSE) -> Roam Kiosk | C9: KE | D9: NBI | E9: A | F9: 07 | G9: =CONCATENATE("#",A9,"-",C9,"-",D9,"-",E9,"-",F9,) -> #RK-KE-NBI-A-07 | H9: =concatenate(G9) -> #RK-KE-NBI-A-07 | L9: =B9&" - "&K9 -> Roam Kiosk - | M9: =CONCATENATE(G9," - Rental Kiosk - ",J9," - ",K9) -> #RK-KE-NBI-A-07 - Rental Kiosk - - | Y9: FALSE | Z9: FALSE
A10: RK | B10: =vlookup(A10,'List of Chargers'!$A$2:$B$5,2,FALSE) -> Roam Kiosk | C10: KE | D10: NBI | E10: A | F10: 08 | G10: =CONCATENATE("#",A10,"-",C10,"-",D10,"-",E10,"-",F10,) -> #RK-KE-NBI-A-08 | H10: =concatenate(G10) -> #RK-KE-NBI-A-08 | L10: =B10&" - "&K10 -> Roam Kiosk - | M10: =CONCATENATE(G10," - Rental Kiosk - ",J10," - ",K10) -> #RK-KE-NBI-A-08 - Rental Kiosk - - | Y10: FALSE | Z10: FALSE
A11: RK | B11: =vlookup(A11,'List of Chargers'!$A$2:$B$5,2,FALSE) -> Roam Kiosk | C11: KE | D11: NBI | E11: A | F11: 09 | G11: =CONCATENATE("#",A11,"-",C11,"-",D11,"-",E11,"-",F11,) -> #RK-KE-NBI-A-09 | H11: =concatenate(G11) -> #RK-KE-NBI-A-09 | L11: =B11&" - "&K11 -> Roam Kiosk - | M11: =CONCATENATE(G11," - Rental Kiosk - ",J11," - ",K11) -> #RK-KE-NBI-A-09 - Rental Kiosk - - | Y11: FALSE | Z11: FALSE
A12: RK | B12: =vlookup(A12,'List of Chargers'!$A$2:$B$5,2,FALSE) -> Roam Kiosk | C12: KE | D12: NBI | E12: A | F12: 10 | G12: =CONCATENATE("#",A12,"-",C12,"-",D12,"-",E12,"-",F12,) -> #RK-KE-NBI-A-10 | H12: =concatenate(G12) -> #RK-KE-NBI-A-10 | L12: =B12&" - "&K12 -> Roam Kiosk - | M12: =CONCATENATE(G12," - Rental Kiosk - ",J12," - ",K12) -> #RK-KE-NBI-A-10 - Rental Kiosk - - | Y12: FALSE | Z12: FALSE
A13: RK | B13: =vlookup(A13,'List of Chargers'!$A$2:$B$5,2,FALSE) -> Roam Kiosk | C13: KE | D13: NBI | E13: A | F13: 11 | G13: =CONCATENATE("#",A13,"-",C13,"-",D13,"-",E13,"-",F13,) -> #RK-KE-NBI-A-11 | H13: =concatenate(G13) -> #RK-KE-NBI-A-11 | L13: =B13&" - "&K13 -> Roam Kiosk - | M13: =CONCATENATE(G13," - Rental Kiosk - ",J13," - ",K13) -> #RK-KE-NBI-A-11 - Rental Kiosk - - | Y13: FALSE | Z13: FALSE
A14: RK | B14: =vlookup(A14,'List of Chargers'!$A$2:$B$5,2,FALSE) -> Roam Kiosk | C14: KE | D14: NBI | E14: A | F14: 12 | G14: =CONCATENATE("#",A14,"-",C14,"-",D14,"-",E14,"-",F14,) -> #RK-KE-NBI-A-12 | H14: =concatenate(G14) -> #RK-KE-NBI-A-12 | L14: =B14&" - "&K14 -> Roam Kiosk - | M14: =CONCATENATE(G14," - Rental Kiosk - ",J14," - ",K14) -> #RK-KE-NBI-A-12 - Rental Kiosk - - | Y14: FALSE | Z14: FALSE
A15: RK | B15: =vlookup(A15,'List of Chargers'!$A$2:$B$5,2,FALSE) -> Roam Kiosk | C15: KE | D15: NBI | E15: A | F15: 13 | G15: =CONCATENATE("#",A15,"-",C15,"-",D15,"-",E15,"-",F15,) -> #RK-KE-NBI-A-13 | H15: =concatenate(G15) -> #RK-KE-NBI-A-13 | L15: =B15&" - "&K15 -> Roam Kiosk - | M15: =CONCATENATE(G15," - Rental Kiosk - ",J15," - ",K15) -> #RK-KE-NBI-A-13 - Rental Kiosk - - | Y15: FALSE | Z15: FALSE
A16: RK | B16: =vlookup(A16,'List of Chargers'!$A$2:$B$5,2,FALSE) -> Roam Kiosk | C16: KE | D16: NBI | E16: A | F16: 14 | G16: =CONCATENATE("#",A16,"-",C16,"-",D16,"-",E16,"-",F16,) -> #RK-KE-NBI-A-14 | H16: =concatenate(G16) -> #RK-KE-NBI-A-14 | L16: =B16&" - "&K16 -> Roam Kiosk - | M16: =CONCATENATE(G16," - Rental Kiosk - ",J16," - ",K16) -> #RK-KE-NBI-A-14 - Rental Kiosk - - | Y16: FALSE | Z16: FALSE
A17: RK | B17: =vlookup(A17,'List of Chargers'!$A$2:$B$5,2,FALSE) -> Roam Kiosk | C17: KE | D17: NBI | E17: A | F17: 15 | G17: =CONCATENATE("#",A17,"-",C17,"-",D17,"-",E17,"-",F17,) -> #RK-KE-NBI-A-15 | H17: =concatenate(G17) -> #RK-KE-NBI-A-15 | L17: =B17&" - "&K17 -> Roam Kiosk - | M17: =CONCATENATE(G17," - Rental Kiosk - ",J17," - ",K17) -> #RK-KE-NBI-A-15 - Rental Kiosk - - | Y17: FALSE | Z17: FALSE
A18: RK | B18: =vlookup(A18,'List of Chargers'!$A$2:$B$5,2,FALSE) -> Roam Kiosk | C18: KE | D18: NBI | E18: A | F18: 16 | G18: =CONCATENATE("#",A18,"-",C18,"-",D18,"-",E18,"-",F18,) -> #RK-KE-NBI-A-16 | H18: =concatenate(G18) -> #RK-KE-NBI-A-16 | L18: =B18&" - "&K18 -> Roam Kiosk - | M18: =CONCATENATE(G18," - Rental Kiosk - ",J18," - ",K18) -> #RK-KE-NBI-A-16 - Rental Kiosk - - | Y18: FALSE | Z18: FALSE
A19: RK | B19: =vlookup(A19,'List of Chargers'!$A$2:$B$5,2,FALSE) -> Roam Kiosk | C19: KE | D19: NBI | E19: A | F19: 17 | G19: =CONCATENATE("#",A19,"-",C19,"-",D19,"-",E19,"-",F19,) -> #RK-KE-NBI-A-17 | H19: =concatenate(G19) -> #RK-KE-NBI-A-17 | L19: =B19&" - "&K19 -> Roam Kiosk - | M19: =CONCATENATE(G19," - Rental Kiosk - ",J19," - ",K19) -> #RK-KE-NBI-A-17 - Rental Kiosk - - | Y19: FALSE | Z19: FALSE
... A22: RK | B22: =vlookup(A22,'List of Chargers'!$A$2:$B$5,2,FALSE) -> Roam Kiosk | C22: KE | D22: NBI | E22: A | F22: 20 | G22: =CONCATENATE("#",A22,"-",C22,"-",D22,"-",E22,"-",F22,) -> #RK-KE-NBI-A-20 | H22: =concatenate(G22) -> #RK-KE-NBI-A-20 | L22: =B22&" - "&K22 -> Roam Kiosk - | M22: =CONCATENATE(G22," - Rental Kiosk - ",J22," - ",K22) -> #RK-KE-NBI-A-20 - Rental Kiosk - - | Y22: FALSE | Z22: FALSE
A23: RK | B23: =vlookup(A23,'List of Chargers'!$A$2:$B$5,2,FALSE) -> Roam Kiosk | C23: KE | D23: NBI | E23: A | F23: 21 | G23: =CONCATENATE("#",A23,"-",C23,"-",D23,"-",E23,"-",F23,) -> #RK-KE-NBI-A-21 | H23: =concatenate(G23) -> #RK-KE-NBI-A-21 | L23: =B23&" - "&K23 -> Roam Kiosk - | M23: =CONCATENATE(G23," - Rental Kiosk - ",J23," - ",K23) -> #RK-KE-NBI-A-21 - Rental Kiosk - -
A24: RK | B24: =vlookup(A24,'List of Chargers'!$A$2:$B$5,2,FALSE) -> Roam Kiosk | C24: KE | D24: NBI | E24: A | F24: 22 | G24: =CONCATENATE("#",A24,"-",C24,"-",D24,"-",E24,"-",F24,) -> #RK-KE-NBI-A-22 | H24: =concatenate(G24) -> #RK-KE-NBI-A-22 | L24: =B24&" - "&K24 -> Roam Kiosk - | M24: =CONCATENATE(G24," - Rental Kiosk - ",J24," - ",K24) -> #RK-KE-NBI-A-22 - Rental Kiosk - -
A25: RK | B25: =vlookup(A25,'List of Chargers'!$A$2:$B$5,2,FALSE) -> Roam Kiosk | C25: KE | D25: NBI | E25: A | F25: 23 | G25: =CONCATENATE("#",A25,"-",C25,"-",D25,"-",E25,"-",F25,) -> #RK-KE-NBI-A-23 | H25: =concatenate(G25) -> #RK-KE-NBI-A-23 | L25: =B25&" - "&K25 -> Roam Kiosk - | M25: =CONCATENATE(G25," - Rental Kiosk - ",J25," - ",K25) -> #RK-KE-NBI-A-23 - Rental Kiosk - -
A26: RK | B26: =vlookup(A26,'List of Chargers'!$A$2:$B$5,2,FALSE) -> Roam Kiosk | C26: KE | D26: NBI | E26: A | F26: 24 | G26: =CONCATENATE("#",A26,"-",C26,"-",D26,"-",E26,"-",F26,) -> #RK-KE-NBI-A-24 | H26: =concatenate(G26) -> #RK-KE-NBI-A-24 | L26: =B26&" - "&K26 -> Roam Kiosk - | M26: =CONCATENATE(G26," - Rental Kiosk - ",J26," - ",K26) -> #RK-KE-NBI-A-24 - Rental Kiosk - -
A27: RK | B27: =vlookup(A27,'List of Chargers'!$A$2:$B$5,2,FALSE) -> Roam Kiosk | C27: KE | D27: NBI | E27: A | F27: 25 | G27: =CONCATENATE("#",A27,"-",C27,"-",D27,"-",E27,"-",F27,) -> #RK-KE-NBI-A-25 | H27: =concatenate(G27) -> #RK-KE-NBI-A-25 | L27: =B27&" - "&K27 -> Roam Kiosk - | M27: =CONCATENATE(G27," - Rental Kiosk - ",J27," - ",K27) -> #RK-KE-NBI-A-25 - Rental Kiosk - -
A28: RK | B28: =vlookup(A28,'List of Chargers'!$A$2:$B$5,2,FALSE) -> Roam Kiosk | C28: KE | D28: NBI | E28: A | F28: 26 | G28: =CONCATENATE("#",A28,"-",C28,"-",D28,"-",E28,"-",F28,) -> #RK-KE-NBI-A-26 | H28: =concatenate(G28) -> #RK-KE-NBI-A-26 | L28: =B28&" - "&K28 -> Roam Kiosk - | M28: =CONCATENATE(G28," - Rental Kiosk - ",J28," - ",K28) -> #RK-KE-NBI-A-26 - Rental Kiosk - -
A29: RK | B29: =vlookup(A29,'List of Chargers'!$A$2:$B$5,2,FALSE) -> Roam Kiosk | C29: KE | D29: NBI | E29: A | F29: 27 | G29: =CONCATENATE("#",A29,"-",C29,"-",D29,"-",E29,"-",F29,) -> #RK-KE-NBI-A-27 | H29: =concatenate(G29) -> #RK-KE-NBI-A-27 | L29: =B29&" - "&K29 -> Roam Kiosk - | M29: =CONCATENATE(G29," - Rental Kiosk - ",J29," - ",K29) -> #RK-KE-NBI-A-27 - Rental Kiosk - -
A30: RK | B30: =vlookup(A30,'List of Chargers'!$A$2:$B$5,2,FALSE) -> Roam Kiosk | C30: KE | D30: NBI | E30: A | F30: 28 | G30: =CONCATENATE("#",A30,"-",C30,"-",D30,"-",E30,"-",F30,) -> #RK-KE-NBI-A-28 | H30: =concatenate(G30) -> #RK-KE-NBI-A-28 | L30: =B30&" - "&K30 -> Roam Kiosk - | M30: =CONCATENATE(G30," - Rental Kiosk - ",J30," - ",K30) -> #RK-KE-NBI-A-28 - Rental Kiosk - -
A31: RK | B31: =vlookup(A31,'List of Chargers'!$A$2:$B$5,2,FALSE) -> Roam Kiosk | C31: KE | D31: NBI | E31: A | F31: 29 | G31: =CONCATENATE("#",A31,"-",C31,"-",D31,"-",E31,"-",F31,) -> #RK-KE-NBI-A-29 | H31: =concatenate(G31) -> #RK-KE-NBI-A-29 | L31: =B31&" - "&K31 -> Roam Kiosk - | M31: =CONCATENATE(G31," - Rental Kiosk - ",J31," - ",K31) -> #RK-KE-NBI-A-29 - Rental Kiosk - -
A32: RK | B32: =vlookup(A32,'List of Chargers'!$A$2:$B$5,2,FALSE) -> Roam Kiosk | C32: KE | D32: NBI | E32: A | F32: 30 | G32: =CONCATENATE("#",A32,"-",C32,"-",D32,"-",E32,"-",F32,) -> #RK-KE-NBI-A-30 | H32: =concatenate(G32) -> #RK-KE-NBI-A-30 | L32: =B32&" - "&K32 -> Roam Kiosk - | M32: =CONCATENATE(G32," - Rental Kiosk - ",J32," - ",K32) -> #RK-KE-NBI-A-30 - Rental Kiosk - -
A33: RK | B33: =vlookup(A33,'List of Chargers'!$A$2:$B$5,2,FALSE) -> Roam Kiosk | C33: KE | D33: NBI | E33: A | F33: 31 | G33: =CONCATENATE("#",A33,"-",C33,"-",D33,"-",E33,"-",F33,) -> #RK-KE-NBI-A-31 | H33: =concatenate(G33) -> #RK-KE-NBI-A-31 | L33: =B33&" - "&K33 -> Roam Kiosk - | M33: =CONCATENATE(G33," - Rental Kiosk - ",J33," - ",K33) -> #RK-KE-NBI-A-31 - Rental Kiosk - -
A34: RK | B34: =vlookup(A34,'List of Chargers'!$A$2:$B$5,2,FALSE) -> Roam Kiosk | C34: KE | D34: NBI | E34: A | F34: 32 | G34: =CONCATENATE("#",A34,"-",C34,"-",D34,"-",E34,"-",F34,) -> #RK-KE-NBI-A-32 | H34: =concatenate(G34) -> #RK-KE-NBI-A-32 | L34: =B34&" - "&K34 -> Roam Kiosk - | M34: =CONCATENATE(G34," - Rental Kiosk - ",J34," - ",K34) -> #RK-KE-NBI-A-32 - Rental Kiosk - -
A35: RK | B35: =vlookup(A35,'List of Chargers'!$A$2:$B$5,2,FALSE) -> Roam Kiosk | C35: KE | D35: NBI | E35: A | F35: 33 | G35: =CONCATENATE("#",A35,"-",C35,"-",D35,"-",E35,"-",F35,) -> #RK-KE-NBI-A-33 | H35: =concatenate(G35) -> #RK-KE-NBI-A-33 | L35: =B35&" - "&K35 -> Roam Kiosk - | M35: =CONCATENATE(G35," - Rental Kiosk - ",J35," - ",K35) -> #RK-KE-NBI-A-33 - Rental Kiosk - -

Sheet KE County Codes
A1: Code | B1: County | C1: Headquarters/ capital | D1: Postal abbreviations
A2: 1 | B2: Mombasa | C2: Mombasa | D2: MSA
A3: 2 | B3: Kwale | C3: Kwale | D3: KWL
A4: 3 | B4: Kilifi | C4: Kilifi | D4: KLF
A5: 4 | B5: Tana River | C5: Hola | D5: TRV
A6: 5 | B6: Lamu | C6: Lamu | D6: LMU
A7: 6 | B7: Taita–Taveta | C7: Mwatate | D7: TVT
A8: 7 | B8: Garissa | C8: Garissa | D8: GRS
A9: 8 | B9: Wajir | C9: Wajir | D9: WJR
A10: 9 | B10: Mandera | C10: Mandera | D10: MDR
A11: 10 | B11: Marsabit | C11: Marsabit | D11: MRS
A12: 11 | B12: Isiolo | C12: Isiolo | D12: ISL
A13: 12 | B13: Meru | C13: Meru | D13: MRU
... A48: 47 | B48: Nairobi | C48: Nairobi | D48: NBI

Sheet FO Project Code
B2: FO-XXX-YY#OUTLET/CHARGER-ID | F2: Link to Field Ops Setup from Dynamics
B4: FO | C4: Field Operation
B5: XXX | C5: Regional ISO Code
B6: YY | C6: Area Number
B8: EXAMPLE
B10: FO-NBI-01#RH-KE-NBI-A-01
B12: FO | C12: Field Operations
B13: NBI | C13: Nairobi Region
B14: 01 | C14: Area 01
B15: #
B16: RH | C16: Roam Hub
B17: KE | C17: Kenya
B18: A | C18: Increment A
B19: 01 | C19: Increment 01
B21: LIST OF REGIONS
B23: Regions | C23: Regions Name
B24: NBI | C24: Greater Nairobi
B27: LIST OF AREAS
B29: Regions | C29: Areas | D29: Prefix | E29: Areas Name
B30: NBI | C30: 01 | D30: =CONCATENATE("FO-",B30,"-",TEXT(C30,"00")) -> FO-NBI-01 | E30: Nairobi Central
B31: NBI | C31: 02 | D31: =CONCATENATE("FO-",B31,"-",TEXT(C31,"00")) -> FO-NBI-02 | E31: Thika
B32: NBI | C32: 03 | D32: =CONCATENATE("FO-",B32,"-",TEXT(C32,"00")) -> FO-NBI-03 | E32: Machakos
B33: NBI | C33: 04 | D33: =CONCATENATE("FO-",B33,"-",TEXT(C33,"00")) -> FO-NBI-04 | E33: Ngong
B34: NBI | C34: 05 | D34: =CONCATENATE("FO-",B34,"-",TEXT(C34,"00")) -> FO-NBI-05 | E34: Kitengela
B35: NBI | C35: 06 | D35: =CONCATENATE("FO-",B35,"-",TEXT(C35,"00")) -> FO-NBI-06 | E35: Rongai / Kiserian

Sheet RH - KE
A1: FIELD OPS ID | C1: OUTLET / ASSET ID | J1: =countif(J3:J502,"Operational") -> 17 | K1: Operational Hubs | L1: Site Information | Q1: Site Manager | S1: Services | U1: =COUNTIFS(U3:U502,TRUE,J3:J502,"Operational") -> 6 | V1: Location Type | X1: Extinguishers | Y1: Serial Numbers | AC1: Safaricom | AE1: Number of Chargers | AL1: KPLC / Power | AP1: Others
A2: Region | B2: Area | C2: Name ID | D2: Asset | E2: Country | F2: Alphabet | G2: No | H2: Roam Charger ID | I2: Dynamics Project Code | J2: Status | K2: Launch Date | L2: Partner | M2: Site Name | N2: Station Name | O2: Long Name | P2: Coordinate | Q2: Full Name | R2: Phone Number | S2: Charging | T2: Rental | U2: After Sales | V2: Container | W2: Shop | X2: Next Date of Control | Y2: 3P Energy Meter | Z2: 1P Energy Meter | AA2: CCTV-interior | AB2: CCTV-exterior | AC2: Direct Line | AD2: 5G Router line | AE2: Total | AF2: Total kW | AG2: 6A | AH2: 9A | AI2: 10A | AJ2: 25A | AK2: 40A | AL2: emobility tarriff | AM2: KPLC Meter | AN2: KPLC Account | AO2: Max kVA | AP2: Ownership | AQ2: Operation | AR2: Battery Rack No. Battery | AS2: Battery Rack Type
A3: NBI | B3: 1 | C3: RH | D3: =vlookup(C3,'List of Chargers'!$A$2:$B$5,2,FALSE) -> Roam Hub | E3: KE | F3: A | G3: 01 | H3: =CONCATENATE("#",C3,"-",E3,"-",F3,"-",G3,) -> #RH-KE-A-01 | I3: =concatenate("FO-",A3,"-",TEXT(B3,"00"),H3) -> FO-NBI-01#RH-KE-A-01 | J3: Operational | K3: 16/01/2025 | L3: TotalEnergies | M3: Outering | N3: =D3&" - "&M3 -> Roam Hub - Outering | O3: =CONCATENATE(I3,": ",N3) -> FO-NBI-01#RH-KE-A-01: Roam Hub - Outering | P3: -1.26955, 36.88024 | Q3: Hardley Sultan | R3: 254723655007 | S3: TRUE | T3: TRUE | U3: FALSE | V3: TRUE | W3: FALSE | Y3: F30F99A0 | Z3: 3BAD8FBE | AA3: FIOJP1906000602 | AB3: FIOJP1906000499 | AC3: 254114930561 | AE3: =sum(AG3:AK3) -> 34 | AF3: =AG3*(6*84/1000)+AH3*(9*84/1000)+AI3*(10*84/1000)+AJ3*(25*84/1000)+AK3*(40*84/1000) -> 40.068 | AH3: 13 | AI3: 11 | AJ3: 10 | AL3: Yes | AM3: 92800552884 | AN3: 167221569 | AP3: Roam Electric Limited | AQ3: Roam Electric Limited
A4: NBI | B4: 1 | C4: RH | D4: =vlookup(C4,'List of Chargers'!$A$2:$B$5,2,FALSE) -> Roam Hub | E4: KE | F4: A | G4: 02 | H4: =CONCATENATE("#",C4,"-",E4,"-",F4,"-",G4,) -> #RH-KE-A-02 | I4: =concatenate("FO-",A4,"-",TEXT(B4,"00"),H4) -> FO-NBI-01#RH-KE-A-02 | J4: Operational | K4: 44931 | L4: TotalEnergies | M4: Wayaki Way | N4: =D4&" - "&M4 -> Roam Hub - Wayaki Way | O4: =CONCATENATE(I4,": ",N4) -> FO-NBI-01#RH-KE-A-02: Roam Hub - Wayaki Way | P4: -1.258610, 36.781386 | Q4: Edwin Kimani | R4: 254727204078 | S4: TRUE | T4: TRUE | U4: TRUE | V4: TRUE | W4: FALSE | AC4: 254113585123 | AE4: =sum(AG4:AK4) -> 36 | AF4: =AG4*(6*84/1000)+AH4*(9*84/1000)+AI4*(10*84/1000)+AJ4*(25*84/1000)+AK4*(40*84/1000) -> 36.036 | AG4: 2 | AH4: 13 | AI4: 15 | AJ4: 6 | AL4: Yes | AM4: 25700631580 | AN4: 163042330 | AP4: Roam Electric Limited | AQ4: Roam Electric Limited
A5: NBI | B5: 1 | C5: RH | D5: =vlookup(C5,'List of Chargers'!$A$2:$B$5,2,FALSE) -> Roam Hub | E5: KE | F5: A | G5: 03 | H5: =CONCATENATE("#",C5,"-",E5,"-",F5,"-",G5,) -> #RH-KE-A-03 | I5: =concatenate("FO-",A5,"-",TEXT(B5,"00"),H5) -> FO-NBI-01#RH-KE-A-03 | J5: Operational | K5: 45296 | L5: Sahara Energy | M5: Kayole | N5: =D5&" - "&M5 -> Roam Hub - Kayole | O5: =CONCATENATE(I5,": ",N5) -> FO-NBI-01#RH-KE-A-03: Roam Hub - Kayole | P5: -1.28173, 36.9052 | Q5: Anthony Mugash | R5: 254721461560 | S5: TRUE | T5: TRUE | U5: TRUE | V5: TRUE | W5: FALSE | AC5: 254700010315 | AE5: =sum(AG5:AK5) -> 37 | AF5: =AG5*(6*84/1000)+AH5*(9*84/1000)+AI5*(10*84/1000)+AJ5*(25*84/1000)+AK5*(40*84/1000) -> 42.84 | AH5: 10 | AI5: 17 | AJ5: 10 | AL5: Yes | AM5: 25700954479 | AN5: 161712787 | AP5: Roam Electric Limited | AQ5: Roam Electric Limited
A6: NBI | B6: 1 | C6: RH | D6: =vlookup(C6,'List of Chargers'!$A$2:$B$5,2,FALSE) -> Roam Hub | E6: KE | F6: A | G6: 04 | H6: =CONCATENATE("#",C6,"-",E6,"-",F6,"-",G6,) -> #RH-KE-A-04 | I6: =concatenate("FO-",A6,"-",TEXT(B6,"00"),H6) -> FO-NBI-01#RH-KE-A-04 | J6: Operational | K6: 44929 | L6: TotalEnergies | M6: Lusaka Road | N6: =D6&" - "&M6 -> Roam Hub - Lusaka Road | O6: =CONCATENATE(I6,": ",N6) -> FO-NBI-01#RH-KE-A-04: Roam Hub - Lusaka Road | P6: -1.301257, 36.833013 | Q6: Moses Masibayi | R6: 254724051752 | S6: TRUE | T6: TRUE | U6: FALSE | V6: TRUE | W6: FALSE | AC6: 254745145482 | AE6: =sum(AG6:AK6) -> 38 | AF6: =AG6*(6*84/1000)+AH6*(9*84/1000)+AI6*(10*84/1000)+AJ6*(25*84/1000)+AK6*(40*84/1000) -> 38.388 | AH6: 13 | AI6: 19 | AJ6: 6 | AL6: Yes | AM6: 25700599993 | AN6: 163042405 | AP6: Roam Electric Limited | AQ6: Roam Electric Limited
A7: NBI | B7: 1 | C7: RH | D7: =vlookup(C7,'List of Chargers'!$A$2:$B$5,2,FALSE) -> Roam Hub | E7: KE | F7: A | G7: 05 | H7: =CONCATENATE("#",C7,"-",E7,"-",F7,"-",G7,) -> #RH-KE-A-05 | I7: =concatenate("FO-",A7,"-",TEXT(B7,"00"),H7) -> FO-NBI-01#RH-KE-A-05 | J7: Operational | K7: 44938 | L7: Quickmart | M7: Roysambu | N7: =D7&" - "&M7 -> Roam Hub - Roysambu | O7: =CONCATENATE(I7,": ",N7) -> FO-NBI-01#RH-KE-A-05: Roam Hub - Roysambu | P7: -1.21521, 36.89175 | Q7: George Chege | R7: 254700838383 | S7: TRUE | T7: TRUE | U7: FALSE | V7: TRUE | W7: FALSE | AC7: 254111917217 | AE7: =sum(AG7:AK7) -> 42 | AF7: =AG7*(6*84/1000)+AH7*(9*84/1000)+AI7*(10*84/1000)+AJ7*(25*84/1000)+AK7*(40*84/1000) -> 47.88 | AI7: 32 | AJ7: 10 | AL7: Yes | AM7: 92802562857 | AN7: 177073766 | AP7: Roam Electric Limited | AQ7: Roam Electric Limited
A8: NBI | B8: 1 | C8: RH | D8: =vlookup(C8,'List of Chargers'!$A$2:$B$5,2,FALSE) -> Roam Hub | E8: KE | F8: A | G8: 06 | H8: =CONCATENATE("#",C8,"-",E8,"-",F8,"-",G8,) -> #RH-KE-A-06 | I8: =concatenate("FO-",A8,"-",TEXT(B8,"00"),H8) -> FO-NBI-01#RH-KE-A-06 | J8: Operational | K8: 45573 | L8: TotalEnergies | M8: Sabaki | N8: =D8&" - "&M8 -> Roam Hub - Sabaki | O8: =CONCATENATE(I8,": ",N8) -> FO-NBI-01#RH-KE-A-06: Roam Hub - Sabaki | P8: -1.41952, 36.95438 | R8: 254114930589 | S8: TRUE | T8: TRUE | U8: FALSE | V8: TRUE | W8: FALSE | AE8: =sum(AG8:AK8) -> 24 | AF8: =AG8*(6*84/1000)+AH8*(9*84/1000)+AI8*(10*84/1000)+AJ8*(25*84/1000)+AK8*(40*84/1000) -> 27.72 | AI8: 18 | AJ8: 6 | AL8: Yes | AM8: 92800485606 | AN8: 175846847 | AP8: Roam Electric Limited | AQ8: Roam Electric Limited
A9: NBI | B9: 1 | C9: RH | D9: =vlookup(C9,'List of Chargers'!$A$2:$B$5,2,FALSE) -> Roam Hub | E9: KE | F9: A | G9: 07 | H9: =CONCATENATE("#",C9,"-",E9,"-",F9,"-",G9,) -> #RH-KE-A-07 | I9: =concatenate("FO-",A9,"-",TEXT(B9,"00"),H9) -> FO-NBI-01#RH-KE-A-07 | J9: Operational | K9: 45300 | L9: Shell | M9: Forest Road | N9: =D9&" - "&M9 -> Roam Hub - Forest Road | O9: =CONCATENATE(I9,": ",N9) -> FO-NBI-01#RH-KE-A-07: Roam Hub - Forest Road | P9: -1.26773, 36.83114 | Q9: Palawaan Bhadrika | R9: 254722528051 | S9: TRUE | T9: TRUE | U9: FALSE | V9: TRUE | W9: FALSE | AC9: 254112685256 | AE9: =sum(AG9:AK9) -> 30 | AF9: =AG9*(6*84/1000)+AH9*(9*84/1000)+AI9*(10*84/1000)+AJ9*(25*84/1000)+AK9*(40*84/1000) -> 31.668 | AH9: 13 | AI9: 11 | AJ9: 6 | AL9: No | AP9: Roam Electric Limited | AQ9: Roam Electric Limited
A10: NBI | B10: 1 | C10: RH | D10: =vlookup(C10,'List of Chargers'!$A$2:$B$5,2,FALSE) -> Roam Hub | E10: KE | F10: A | G10: 08 | H10: =CONCATENATE("#",C10,"-",E10,"-",F10,"-",G10,) -> #RH-KE-A-08 | I10: =concatenate("FO-",A10,"-",TEXT(B10,"00"),H10) -> FO-NBI-01#RH-KE-A-08 | J10: Operational | K10: 45717 | L10: TotalEnergies | M10: Karambee | N10: =D10&" - "&M10 -> Roam Hub - Karambee | O10: =CONCATENATE(I10,": ",N10) -> FO-NBI-01#RH-KE-A-08: Roam Hub - Karambee | P10: -1.26673, 36.84522 | R10: 254117473213 | S10: TRUE | T10: TRUE | U10: FALSE | V10: TRUE | W10: FALSE | AC10: 254117473213 | AE10: =sum(AG10:AK10) -> 31 | AF10: =AG10*(6*84/1000)+AH10*(9*84/1000)+AI10*(10*84/1000)+AJ10*(25*84/1000)+AK10*(40*84/1000) -> 37.38 | AH10: 15 | AI10: 6 | AJ10: 10 | AL10: No | AM10: 92800562289 | AN10: 169093444 | AP10: Roam Electric Limited | AQ10: Roam Electric Limited
A11: NBI | B11: 1 | C11: RH | D11: =vlookup(C11,'List of Chargers'!$A$2:$B$5,2,FALSE) -> Roam Hub | E11: KE | F11: A | G11: 09 | H11: =CONCATENATE("#",C11,"-",E11,"-",F11,"-",G11,) -> #RH-KE-A-09 | I11: =concatenate("FO-",A11,"-",TEXT(B11,"00"),H11) -> FO-NBI-01#RH-KE-A-09 | J11: Construction | K11: Container 2 | L11: Oryx | M11: Oryx Ruai | N11: =D11&" - "&M11 -> Roam Hub - Oryx Ruai | O11: =CONCATENATE(I11,": ",N11) -> FO-NBI-01#RH-KE-A-09: Roam Hub - Oryx Ruai | P11: -1.25481, 36.98606 | S11: TRUE | T11: TRUE | U11: FALSE | V11: TRUE | W11: FALSE | AE11: =sum(AG11:AK11) -> 0 | AF11: =AG11*(6*84/1000)+AH11*(9*84/1000)+AI11*(10*84/1000)+AJ11*(25*84/1000)+AK11*(40*84/1000) -> 0 | AL11: No | AP11: Roam Electric Limited | AQ11: Roam Electric Limited
A12: NBI | B12: 3 | C12: RH | D12: =vlookup(C12,'List of Chargers'!$A$2:$B$5,2,FALSE) -> Roam Hub | E12: KE | F12: A | G12: 10 | H12: =CONCATENATE("#",C12,"-",E12,"-",F12,"-",G12,) -> #RH-KE-A-10 | I12: =concatenate("FO-",A12,"-",TEXT(B12,"00"),H12) -> FO-NBI-03#RH-KE-A-10 | J12: Operational | L12: Stanchard | M12: Machakos Town | N12: =D12&" - "&M12 -> Roam Hub - Machakos Town | O12: =CONCATENATE(I12,": ",N12) -> FO-NBI-03#RH-KE-A-10: Roam Hub - Machakos Town | P12: -1.51997, 37.26909 | S12: TRUE | T12: TRUE | U12: FALSE | V12: TRUE | W12: FALSE | AE12: =sum(AG12:AK12) -> 16 | AF12: =AG12*(6*84/1000)+AH12*(9*84/1000)+AI12*(10*84/1000)+AJ12*(25*84/1000)+AK12*(40*84/1000) -> 21 | AI12: 10 | AJ12: 6 | AL12: No | AP12: Roam Electric Limited | AQ12: Roam Electric Limited
A13: NBI | B13: 1 | C13: RH | D13: =vlookup(C13,'List of Chargers'!$A$2:$B$5,2,FALSE) -> Roam Hub | E13: KE | F13: A | G13: 11 | H13: =CONCATENATE("#",C13,"-",E13,"-",F13,"-",G13,) -> #RH-KE-A-11 | I13: =concatenate("FO-",A13,"-",TEXT(B13,"00"),H13) -> FO-NBI-01#RH-KE-A-11 | J13: Operational | K13: 15/11/2025 | L13: Rubis | M13: Ojijo | N13: =D13&" - "&M13 -> Roam Hub - Ojijo | O13: =CONCATENATE(I13,": ",N13) -> FO-NBI-01#RH-KE-A-11: Roam Hub - Ojijo | P13: -1.2671, 36.81175 | S13: TRUE | T13: TRUE | U13: FALSE | V13: TRUE | W13: FALSE | AE13: =sum(AG13:AK13) -> 30 | AF13: =AG13*(6*84/1000)+AH13*(9*84/1000)+AI13*(10*84/1000)+AJ13*(25*84/1000)+AK13*(40*84/1000) -> 31.92 | AH13: 10 | AI13: 14 | AJ13: 6 | AL13: No | AM13: 92800546290 | AN13: 179263787 | AP13: Roam Electric Limited | AQ13: Roam Electric Limited
A14: NBI | C14: RH | D14: =vlookup(C14,'List of Chargers'!$A$2:$B$5,2,FALSE) -> Roam Hub | E14: KE | F14: A | G14: 12 | H14: =CONCATENATE("#",C14,"-",E14,"-",F14,"-",G14,) -> #RH-KE-A-12 | I14: =concatenate("FO-",A14,"-",TEXT(B14,"00"),H14) -> FO-NBI-00#RH-KE-A-12 | K14: Container 3 | N14: =D14&" - "&M14 -> Roam Hub - | O14: =CONCATENATE(I14,": ",N14) -> FO-NBI-00#RH-KE-A-12: Roam Hub - | S14: TRUE | T14: TRUE | U14: FALSE | V14: TRUE | W14: FALSE | AE14: =sum(AG14:AK14) -> 0 | AF14: =AG14*(6*84/1000)+AH14*(9*84/1000)+AI14*(10*84/1000)+AJ14*(25*84/1000)+AK14*(40*84/1000) -> 0
A15: NBI | C15: RH | D15: =vlookup(C15,'List of Chargers'!$A$2:$B$5,2,FALSE) -> Roam Hub | E15: KE | F15: A | G15: 13 | H15: =CONCATENATE("#",C15,"-",E15,"-",F15,"-",G15,) -> #RH-KE-A-13 | I15: =concatenate("FO-",A15,"-",TEXT(B15,"00"),H15) -> FO-NBI-00#RH-KE-A-13 | N15: =D15&" - "&M15 -> Roam Hub - | O15: =CONCATENATE(I15,": ",N15) -> FO-NBI-00#RH-KE-A-13: Roam Hub - | S15: FALSE | T15: FALSE | U15: FALSE | V15: TRUE | W15: FALSE | AE15: =sum(AG15:AK15) -> 0 | AF15: =AG15*(6*84/1000)+AH15*(9*84/1000)+AI15*(10*84/1000)+AJ15*(25*84/1000)+AK15*(40*84/1000) -> 0
A16: NBI | C16: RH | D16: =vlookup(C16,'List of Chargers'!$A$2:$B$5,2,FALSE) -> Roam Hub | E16: KE | F16: A | G16: 14 | H16: =CONCATENATE("#",C16,"-",E16,"-",F16,"-",G16,) -> #RH-KE-A-14 | I16: =concatenate("FO-",A16,"-",TEXT(B16,"00"),H16) -> FO-NBI-00#RH-KE-A-14 | N16: =D16&" - "&M16 -> Roam Hub - | O16: =CONCATENATE(I16,": ",N16) -> FO-NBI-00#RH-KE-A-14: Roam Hub - | S16: FALSE | T16: FALSE | U16: FALSE | V16: TRUE | W16: FALSE | AE16: =sum(AG16:AK16) -> 0 | AF16: =AG16*(6*84/1000)+AH16*(9*84/1000)+AI16*(10*84/1000)+AJ16*(25*84/1000)+AK16*(40*84/1000) -> 0
A17: NBI | C17: RH | D17: =vlookup(C17,'List of Chargers'!$A$2:$B$5,2,FALSE) -> Roam Hub | E17: KE | F17: A | G17: 15 | H17: =CONCATENATE("#",C17,"-",E17,"-",F17,"-",G17,) -> #RH-KE-A-15 | I17: =concatenate("FO-",A17,"-",TEXT(B17,"00"),H17) -> FO-NBI-00#RH-KE-A-15 | N17: =D17&" - "&M17 -> Roam Hub - | O17: =CONCATENATE(I17,": ",N17) -> FO-NBI-00#RH-KE-A-15: Roam Hub - | S17: FALSE | T17: FALSE | U17: FALSE | V17: TRUE | W17: FALSE | AE17: =sum(AG17:AK17) -> 0 | AF17: =AG17*(6*84/1000)+AH17*(9*84/1000)+AI17*(10*84/1000)+AJ17*(25*84/1000)+AK17*(40*84/1000) -> 0
A18: NBI | B18: 1 | C18: RH | D18: =vlookup(C18,'List of Chargers'!$A$2:$B$5,2,FALSE) -> Roam Hub | E18: KE | F18: A | G18: 16 | H18: =CONCATENATE("#",C18,"-",E18,"-",F18,"-",G18,) -> #RH-KE-A-16 | I18: =concatenate("FO-",A18,"-",TEXT(B18,"00"),H18) -> FO-NBI-01#RH-KE-A-16 | J18: Operational | K18: 17/2/2025 | L18: Roam | M18: Roam Park | N18: =D18&" - "&M18 -> Roam Hub - Roam Park | O18: =CONCATENATE(I18,": ",N18) -> FO-NBI-01#RH-KE-A-16: Roam Hub - Roam Park | P18: -1.33688, 36.8646 | S18: FALSE | T18: FALSE | U18: FALSE | V18: TRUE | W18: FALSE | AE18: =sum(AG18:AK18) -> 18 | AF18: =AG18*(6*84/1000)+AH18*(9*84/1000)+AI18*(10*84/1000)+AJ18*(25*84/1000)+AK18*(40*84/1000) -> 37.8 | AJ18: 18 | AL18: No | AP18: Roam Electric Limited | AQ18: Roam Electric Limited
A19: NBI | B19: 1 | C19: RH | D19: =vlookup(C19,'List of Chargers'!$A$2:$B$5,2,FALSE) -> Roam Hub | E19: KE | F19: A | G19: 17 | H19: =CONCATENATE("#",C19,"-",E19,"-",F19,"-",G19,) -> #RH-KE-A-17 | I19: =concatenate("FO-",A19,"-",TEXT(B19,"00"),H19) -> FO-NBI-01#RH-KE-A-17 | J19: Operational | K19: 28/11/2024 | L19: Roam | M19: Suguta | N19: =D19&" - "&M19 -> Roam Hub - Suguta | O19: =CONCATENATE(I19,": ",N19) -> FO-NBI-01#RH-KE-A-17: Roam Hub - Suguta | P19: -1.28777, 36.77884 | Q19: Nasri Sahal | R19: 724148162 | S19: TRUE | T19: TRUE | U19: FALSE | V19: FALSE | W19: TRUE | AC19: 254704264393 | AE19: =sum(AG19:AK19) -> 60 | AF19: =AG19*(6*84/1000)+AH19*(9*84/1000)+AI19*(10*84/1000)+AJ19*(25*84/1000)+AK19*(40*84/1000) -> 53.508 | AG19: 6 | AH19: 29 | AI19: 19 | AJ19: 6 | AL19: No | AP19: Roam Electric Limited | AQ19: Roam Electric Limited
A20: NBI | B20: 1 | C20: RH | D20: =vlookup(C20,'List of Chargers'!$A$2:$B$5,2,FALSE) -> Roam Hub | E20: KE | F20: A | G20: 18 | H20: =CONCATENATE("#",C20,"-",E20,"-",F20,"-",G20,) -> #RH-KE-A-18 | I20: =concatenate("FO-",A20,"-",TEXT(B20,"00"),H20) -> FO-NBI-01#RH-KE-A-18 | K20: Closed | L20: Greenwheels | M20: GreenWheels HQ | N20: =D20&" - "&M20 -> Roam Hub - GreenWheels HQ | O20: =CONCATENATE(I20,": ",N20) -> FO-NBI-01#RH-KE-A-18: Roam Hub - GreenWheels HQ | S20: FALSE | T20: FALSE | U20: FALSE | V20: FALSE | W20: FALSE | AE20: =sum(AG20:AK20) -> 0 | AF20: =AG20*(6*84/1000)+AH20*(9*84/1000)+AI20*(10*84/1000)+AJ20*(25*84/1000)+AK20*(40*84/1000) -> 0
A21: NBI | B21: 2 | C21: RH | D21: =vlookup(C21,'List of Chargers'!$A$2:$B$5,2,FALSE) -> Roam Hub | E21: KE | F21: A | G21: 19 | H21: =CONCATENATE("#",C21,"-",E21,"-",F21,"-",G21,) -> #RH-KE-A-19 | I21: =concatenate("FO-",A21,"-",TEXT(B21,"00"),H21) -> FO-NBI-02#RH-KE-A-19 | J21: Operational | K21: 45515 | L21: Roam | M21: Thika Centre | N21: =D21&" - "&M21 -> Roam Hub - Thika Centre | O21: =CONCATENATE(I21,": ",N21) -> FO-NBI-02#RH-KE-A-19: Roam Hub - Thika Centre | P21: -1.03381, 37.07543 | R21: 254704 269168 | S21: TRUE | T21: TRUE | U21: TRUE | V21: FALSE | W21: TRUE | AC21: 254704269168 | AD21: 254724322965 | AE21: =sum(AG21:AK21) -> 15 | AF21: =AG21*(6*84/1000)+AH21*(9*84/1000)+AI21*(10*84/1000)+AJ21*(25*84/1000)+AK21*(40*84/1000) -> 12.6 | AI21: 15 | AL21: Yes | AM21: 92800511104 | AN21: 167723861 | AP21: Roam Electric Limited | AQ21: Roam Electric Limited
A22: NBI | B22: 3 | C22: RH | D22: =vlookup(C22,'List of Chargers'!$A$2:$B$5,2,FALSE) -> Roam Hub | E22: KE | F22: A | G22: 20 | H22: =CONCATENATE("#",C22,"-",E22,"-",F22,"-",G22,) -> #RH-KE-A-20 | I22: =concatenate("FO-",A22,"-",TEXT(B22,"00"),H22) -> FO-NBI-03#RH-KE-A-20 | J22: Operational | K22: 30/04/2025 | L22: TotalEnergies | M22: Machakos Centre | N22: =D22&" - "&M22 -> Roam Hub - Machakos Centre | O22: =CONCATENATE(I22,": ",N22) -> FO-NBI-03#RH-KE-A-20: Roam Hub - Machakos Centre | P22: -1.52782, 37.20929 | R22: 254116879836 | S22: TRUE | T22: TRUE | U22: TRUE | V22: FALSE | W22: TRUE | AE22: =sum(AG22:AK22) -> 10 | AF22: =AG22*(6*84/1000)+AH22*(9*84/1000)+AI22*(10*84/1000)+AJ22*(25*84/1000)+AK22*(40*84/1000) -> 8.4 | AI22: 10 | AL22: No | AM22: 277800051124 | AN22: 179361789 | AP22: Roam Electric Limited | AQ22: Roam Electric Limited
A23: NBI | B23: 1 | C23: RH | D23: =vlookup(C23,'List of Chargers'!$A$2:$B$5,2,FALSE) -> Roam Hub | E23: KE | F23: A | G23: 21 | H23: =CONCATENATE("#",C23,"-",E23,"-",F23,"-",G23,) -> #RH-KE-A-21 | I23: =concatenate("FO-",A23,"-",TEXT(B23,"00"),H23) -> FO-NBI-01#RH-KE-A-21 | J23: Operational | K23: 15/07/2025 | L23: Roam | M23: Narobi Regional Office | N23: =D23&" - "&M23 -> Roam Hub - Narobi Regional Office | O23: =CONCATENATE(I23,": ",N23) -> FO-NBI-01#RH-KE-A-21: Roam Hub - Narobi Regional Office | P23: -1.30187, 36.8332 | S23: TRUE | T23: TRUE | U23: TRUE | V23: FALSE | W23: TRUE | AE23: =sum(AG23:AK23) -> 61 | AF23: =AG23*(6*84/1000)+AH23*(9*84/1000)+AI23*(10*84/1000)+AJ23*(25*84/1000)+AK23*(40*84/1000) -> 51.24 | AI23: 61 | AL23: No | AP23: Roam Electric Limited | AQ23: Roam Electric Limited
A24: NBI | B24: 4 | C24: RH | D24: =vlookup(C24,'List of Chargers'!$A$2:$B$5,2,FALSE) -> Roam Hub | E24: KE | F24: A | G24: 22 | H24: =CONCATENATE("#",C24,"-",E24,"-",F24,"-",G24,) -> #RH-KE-A-22 | I24: =concatenate("FO-",A24,"-",TEXT(B24,"00"),H24) -> FO-NBI-04#RH-KE-A-22 | L24: Roam / Ridewell | M24: Ngong Center | N24: =D24&" - "&M24 -> Roam Hub - Ngong Center | O24: =CONCATENATE(I24,": ",N24) -> FO-NBI-04#RH-KE-A-22: Roam Hub - Ngong Center | S24: TRUE | T24: TRUE | U24: TRUE | V24: FALSE | W24: TRUE | AE24: =sum(AG24:AK24) -> 0 | AF24: =AG24*(6*84/1000)+AH24*(9*84/1000)+AI24*(10*84/1000)+AJ24*(25*84/1000)+AK24*(40*84/1000) -> 0
A25: NBI | B25: 1 | C25: RH | D25: =vlookup(C25,'List of Chargers'!$A$2:$B$5,2,FALSE) -> Roam Hub | E25: KE | F25: A | G25: 23 | H25: =CONCATENATE("#",C25,"-",E25,"-",F25,"-",G25,) -> #RH-KE-A-23 | I25: =concatenate("FO-",A25,"-",TEXT(B25,"00"),H25) -> FO-NBI-01#RH-KE-A-23 | J25: Operational | K25: 45969 | L25: Adam's Minimall | M25: Adam's Minimall | N25: =D25&" - "&M25 -> Roam Hub - Adam's Minimall | O25: =CONCATENATE(I25,": ",N25) -> FO-NBI-01#RH-KE-A-23: Roam Hub - Adam's Minimall | P25: -1.30085, 36.77946 | S25: TRUE | T25: TRUE | U25: TRUE | V25: FALSE | W25: TRUE | AE25: =sum(AG25:AK25) -> 79 | AF25: =AG25*(6*84/1000)+AH25*(9*84/1000)+AI25*(10*84/1000)+AJ25*(25*84/1000)+AK25*(40*84/1000) -> 77.7 | AI25: 70 | AJ25: 9 | AL25: Yes | AM25: 25700889873 | AN25: 177047802 | AP25: Roam Electric Limited | AQ25: Roam Electric Limited
A26: NBI | B26: 1 | C26: RH | D26: =vlookup(C26,'List of Chargers'!$A$2:$B$5,2,FALSE) -> Roam Hub | E26: KE | F26: A | G26: 24 | H26: =CONCATENATE("#",C26,"-",E26,"-",F26,"-",G26,) -> #RH-KE-A-24 | I26: =concatenate("FO-",A26,"-",TEXT(B26,"00"),H26) -> FO-NBI-01#RH-KE-A-24 | J26: Operational | K26: 46113 | L26: Roam | M26: Langata | N26: =D26&" - "&M26 -> Roam Hub - Langata | O26: =CONCATENATE(I26,": ",N26) -> FO-NBI-01#RH-KE-A-24: Roam Hub - Langata | P26: -1.34207, 36.7639 | S26: TRUE | T26: TRUE | U26: FALSE | V26: FALSE | W26: TRUE | AE26: =sum(AG26:AK26) -> 30 | AF26: =AG26*(6*84/1000)+AH26*(9*84/1000)+AI26*(10*84/1000)+AJ26*(25*84/1000)+AK26*(40*84/1000) -> 25.2 | AI26: 30 | AL26: No | AM26: 45704547319 | AN26: 175573658 | AP26: Roam Electric Limited | AQ26: Roam Electric Limited
A27: NBI | B27: 1 | C27: RH | D27: =vlookup(C27,'List of Chargers'!$A$2:$B$5,2,FALSE) -> Roam Hub | E27: KE | F27: A | G27: 25 | H27: =CONCATENATE("#",C27,"-",E27,"-",F27,"-",G27,) -> #RH-KE-A-25 | I27: =concatenate("FO-",A27,"-",TEXT(B27,"00"),H27) -> FO-NBI-01#RH-KE-A-25 | J27: Construction | L27: Trinity | M27: Banana | N27: =D27&" - "&M27 -> Roam Hub - Banana | O27: =CONCATENATE(I27,": ",N27) -> FO-NBI-01#RH-KE-A-25: Roam Hub - Banana | P27: -1.16696, 36.75373 | S27: TRUE | T27: TRUE | U27: FALSE | V27: FALSE | W27: TRUE | AE27: =sum(AG27:AK27) -> 0 | AF27: =AG27*(6*84/1000)+AH27*(9*84/1000)+AI27*(10*84/1000)+AJ27*(25*84/1000)+AK27*(40*84/1000) -> 0 | AL27: No | AP27: Roam Electric Limited | AQ27: Roam Electric Limited
A28: NBI | C28: RH | D28: =vlookup(C28,'List of Chargers'!$A$2:$B$5,2,FALSE) -> Roam Hub | E28: KE | F28: A | G28: 26 | H28: =CONCATENATE("#",C28,"-",E28,"-",F28,"-",G28,) -> #RH-KE-A-26 | I28: =concatenate("FO-",A28,"-",TEXT(B28,"00"),H28) -> FO-NBI-00#RH-KE-A-26 | N28: =D28&" - "&M28 -> Roam Hub - | O28: =CONCATENATE(I28,": ",N28) -> FO-NBI-00#RH-KE-A-26: Roam Hub - | S28: FALSE | T28: FALSE | U28: FALSE | V28: FALSE | W28: FALSE | AE28: =sum(AG28:AK28) -> 0 | AF28: =AG28*(6*84/1000)+AH28*(9*84/1000)+AI28*(10*84/1000)+AJ28*(25*84/1000)+AK28*(40*84/1000) -> 0
A29: NBI | C29: RH | D29: =vlookup(C29,'List of Chargers'!$A$2:$B$5,2,FALSE) -> Roam Hub | E29: KE | F29: A | G29: 27 | H29: =CONCATENATE("#",C29,"-",E29,"-",F29,"-",G29,) -> #RH-KE-A-27 | I29: =concatenate("FO-",A29,"-",TEXT(B29,"00"),H29) -> FO-NBI-00#RH-KE-A-27 | N29: =D29&" - "&M29 -> Roam Hub - | O29: =CONCATENATE(I29,": ",N29) -> FO-NBI-00#RH-KE-A-27: Roam Hub - | S29: FALSE | T29: FALSE | U29: FALSE | V29: FALSE | W29: FALSE | AE29: =sum(AG29:AK29) -> 0 | AF29: =AG29*(6*84/1000)+AH29*(9*84/1000)+AI29*(10*84/1000)+AJ29*(25*84/1000)+AK29*(40*84/1000) -> 0
A30: NBI | C30: RH | D30: =vlookup(C30,'List of Chargers'!$A$2:$B$5,2,FALSE) -> Roam Hub | E30: KE | F30: A | G30: 28 | H30: =CONCATENATE("#",C30,"-",E30,"-",F30,"-",G30,) -> #RH-KE-A-28 | I30: =concatenate("FO-",A30,"-",TEXT(B30,"00"),H30) -> FO-NBI-00#RH-KE-A-28 | N30: =D30&" - "&M30 -> Roam Hub - | O30: =CONCATENATE(I30,": ",N30) -> FO-NBI-00#RH-KE-A-28: Roam Hub - | S30: FALSE | T30: FALSE | U30: FALSE | V30: FALSE | W30: FALSE | AE30: =sum(AG30:AK30) -> 0 | AF30: =AG30*(6*84/1000)+AH30*(9*84/1000)+AI30*(10*84/1000)+AJ30*(25*84/1000)+AK30*(40*84/1000) -> 0
A31: NBI | C31: RH | D31: =vlookup(C31,'List of Chargers'!$A$2:$B$5,2,FALSE) -> Roam Hub | E31: KE | F31: A | G31: 29 | H31: =CONCATENATE("#",C31,"-",E31,"-",F31,"-",G31,) -> #RH-KE-A-29 | I31: =concatenate("FO-",A31,"-",TEXT(B31,"00"),H31) -> FO-NBI-00#RH-KE-A-29 | N31: =D31&" - "&M31 -> Roam Hub - | O31: =CONCATENATE(I31,": ",N31) -> FO-NBI-00#RH-KE-A-29: Roam Hub - | S31: FALSE | T31: FALSE | U31: FALSE | V31: FALSE | W31: FALSE | AE31: =sum(AG31:AK31) -> 0 | AF31: =AG31*(6*84/1000)+AH31*(9*84/1000)+AI31*(10*84/1000)+AJ31*(25*84/1000)+AK31*(40*84/1000) -> 0
A32: NBI | C32: RH | D32: =vlookup(C32,'List of Chargers'!$A$2:$B$5,2,FALSE) -> Roam Hub | E32: KE | F32: A | G32: 30 | H32: =CONCATENATE("#",C32,"-",E32,"-",F32,"-",G32,) -> #RH-KE-A-30 | I32: =concatenate("FO-",A32,"-",TEXT(B32,"00"),H32) -> FO-NBI-00#RH-KE-A-30 | N32: =D32&" - "&M32 -> Roam Hub - | O32: =CONCATENATE(I32,": ",N32) -> FO-NBI-00#RH-KE-A-30: Roam Hub - | S32: FALSE | T32: FALSE | U32: FALSE | V32: FALSE | W32: FALSE | AE32: =sum(AG32:AK32) -> 0 | AF32: =AG32*(6*84/1000)+AH32*(9*84/1000)+AI32*(10*84/1000)+AJ32*(25*84/1000)+AK32*(40*84/1000) -> 0
A33: NBI | C33: RH | D33: =vlookup(C33,'List of Chargers'!$A$2:$B$5,2,FALSE) -> Roam Hub | E33: KE | F33: A | G33: 31 | H33: =CONCATENATE("#",C33,"-",E33,"-",F33,"-",G33,) -> #RH-KE-A-31 | I33: =concatenate("FO-",A33,"-",TEXT(B33,"00"),H33) -> FO-NBI-00#RH-KE-A-31 | N33: =D33&" - "&M33 -> Roam Hub - | O33: =CONCATENATE(I33,": ",N33) -> FO-NBI-00#RH-KE-A-31: Roam Hub - | S33: FALSE | T33: FALSE | U33: FALSE | V33: FALSE | W33: FALSE | AE33: =sum(AG33:AK33) -> 0 | AF33: =AG33*(6*84/1000)+AH33*(9*84/1000)+AI33*(10*84/1000)+AJ33*(25*84/1000)+AK33*(40*84/1000) -> 0
A34: NBI | C34: RH | D34: =vlookup(C34,'List of Chargers'!$A$2:$B$5,2,FALSE) -> Roam Hub | E34: KE | F34: A | G34: 32 | H34: =CONCATENATE("#",C34,"-",E34,"-",F34,"-",G34,) -> #RH-KE-A-32 | I34: =concatenate("FO-",A34,"-",TEXT(B34,"00"),H34) -> FO-NBI-00#RH-KE-A-32 | N34: =D34&" - "&M34 -> Roam Hub - | O34: =CONCATENATE(I34,": ",N34) -> FO-NBI-00#RH-KE-A-32: Roam Hub - | S34: FALSE | T34: FALSE | U34: FALSE | V34: FALSE | W34: FALSE | AE34: =sum(AG34:AK34) -> 0 | AF34: =AG34*(6*84/1000)+AH34*(9*84/1000)+AI34*(10*84/1000)+AJ34*(25*84/1000)+AK34*(40*84/1000) -> 0
A35: NBI | C35: RH | D35: =vlookup(C35,'List of Chargers'!$A$2:$B$5,2,FALSE) -> Roam Hub | E35: KE | F35: A | G35: 33 | H35: =CONCATENATE("#",C35,"-",E35,"-",F35,"-",G35,) -> #RH-KE-A-33 | I35: =concatenate("FO-",A35,"-",TEXT(B35,"00"),H35) -> FO-NBI-00#RH-KE-A-33 | N35: =D35&" - "&M35 -> Roam Hub - | O35: =CONCATENATE(I35,": ",N35) -> FO-NBI-00#RH-KE-A-33: Roam Hub - | S35: FALSE | T35: FALSE | U35: FALSE | V35: FALSE | W35: FALSE | AE35: =sum(AG35:AK35) -> 0 | AF35: =AG35*(6*84/1000)+AH35*(9*84/1000)+AI35*(10*84/1000)+AJ35*(25*84/1000)+AK35*(40*84/1000) -> 0
A36: NBI | C36: RH | D36: =vlookup(C36,'List of Chargers'!$A$2:$B$5,2,FALSE) -> Roam Hub | E36: KE | F36: A | G36: 34 | H36: =CONCATENATE("#",C36,"-",E36,"-",F36,"-",G36,) -> #RH-KE-A-34 | I36: =concatenate("FO-",A36,"-",TEXT(B36,"00"),H36) -> FO-NBI-00#RH-KE-A-34 | N36: =D36&" - "&M36 -> Roam Hub - | O36: =CONCATENATE(I36,": ",N36) -> FO-NBI-00#RH-KE-A-34: Roam Hub - | S36: FALSE | T36: FALSE | U36: FALSE | V36: FALSE | W36: FALSE | AE36: =sum(AG36:AK36) -> 0 | AF36: =AG36*(6*84/1000)+AH36*(9*84/1000)+AI36*(10*84/1000)+AJ36*(25*84/1000)+AK36*(40*84/1000) -> 0
A37: NBI | C37: RH | D37: =vlookup(C37,'List of Chargers'!$A$2:$B$5,2,FALSE) -> Roam Hub | E37: KE | F37: A | G37: 35 | H37: =CONCATENATE("#",C37,"-",E37,"-",F37,"-",G37,) -> #RH-KE-A-35 | I37: =concatenate("FO-",A37,"-",TEXT(B37,"00"),H37) -> FO-NBI-00#RH-KE-A-35 | N37: =D37&" - "&M37 -> Roam Hub - | O37: =CONCATENATE(I37,": ",N37) -> FO-NBI-00#RH-KE-A-35: Roam Hub - | S37: FALSE | T37: FALSE | U37: FALSE | V37: FALSE | W37: FALSE | AE37: =sum(AG37:AK37) -> 0 | AF37: =AG37*(6*84/1000)+AH37*(9*84/1000)+AI37*(10*84/1000)+AJ37*(25*84/1000)+AK37*(40*84/1000) -> 0
A38: NBI | C38: RH | D38: =vlookup(C38,'List of Chargers'!$A$2:$B$5,2,FALSE) -> Roam Hub | E38: KE | F38: A | G38: 36 | H38: =CONCATENATE("#",C38,"-",E38,"-",F38,"-",G38,) -> #RH-KE-A-36 | I38: =concatenate("FO-",A38,"-",TEXT(B38,"00"),H38) -> FO-NBI-00#RH-KE-A-36 | N38: =D38&" - "&M38 -> Roam Hub - | O38: =CONCATENATE(I38,": ",N38) -> FO-NBI-00#RH-KE-A-36: Roam Hub - | S38: FALSE | T38: FALSE | U38: FALSE | V38: FALSE | W38: FALSE | AE38: =sum(AG38:AK38) -> 0 | AF38: =AG38*(6*84/1000)+AH38*(9*84/1000)+AI38*(10*84/1000)+AJ38*(25*84/1000)+AK38*(40*84/1000) -> 0
A39: NBI | C39: RH | D39: =vlookup(C39,'List of Chargers'!$A$2:$B$5,2,FALSE) -> Roam Hub | E39: KE | F39: A | G39: 37 | H39: =CONCATENATE("#",C39,"-",E39,"-",F39,"-",G39,) -> #RH-KE-A-37 | I39: =concatenate("FO-",A39,"-",TEXT(B39,"00"),H39) -> FO-NBI-00#RH-KE-A-37 | N39: =D39&" - "&M39 -> Roam Hub - | O39: =CONCATENATE(I39,": ",N39) -> FO-NBI-00#RH-KE-A-37: Roam Hub - | S39: FALSE | T39: FALSE | U39: FALSE | V39: FALSE | W39: FALSE | AE39: =sum(AG39:AK39) -> 0 | AF39: =AG39*(6*84/1000)+AH39*(9*84/1000)+AI39*(10*84/1000)+AJ39*(25*84/1000)+AK39*(40*84/1000) -> 0
A40: NBI | C40: RH | D40: =vlookup(C40,'List of Chargers'!$A$2:$B$5,2,FALSE) -> Roam Hub | E40: KE | F40: A | G40: 38 | H40: =CONCATENATE("#",C40,"-",E40,"-",F40,"-",G40,) -> #RH-KE-A-38 | I40: =concatenate("FO-",A40,"-",TEXT(B40,"00"),H40) -> FO-NBI-00#RH-KE-A-38 | N40: =D40&" - "&M40 -> Roam Hub - | O40: =CONCATENATE(I40,": ",N40) -> FO-NBI-00#RH-KE-A-38: Roam Hub - | S40: FALSE | T40: FALSE | U40: FALSE | V40: FALSE | W40: FALSE | AE40: =sum(AG40:AK40) -> 0 | AF40: =AG40*(6*84/1000)+AH40*(9*84/1000)+AI40*(10*84/1000)+AJ40*(25*84/1000)+AK40*(40*84/1000) -> 0
...

Sheet RP - KE
A1: FIELD OPS | J1: =countif(J3:J1001,"Operational") -> 0 | K1: Operational Points | L1: Site Information | Q1: Site Manager | S1: Serial Numbers | T1: emobility tarriff | U1: KPLC Meter | V1: KPLC Account
A2: Region | B2: Area | C2: Short Name | D2: Long Name | E2: Country | F2: Alphabet | G2: No | H2: Roam Charge Station ID | I2: Dynamics Project Code | J2: Status | K2: Launch Date | L2: Partner | M2: Site Name | N2: Charger Name | O2: Complete Name | P2: Coordinate | Q2: Full Name | R2: Phone Number | S2: 1P Energy Meter | T2: Yes / No | U2: No. | V2: No. | W2: Ownership | X2: Operation | Y2: Socket v1.2 | Z2: 6kW DC 1xType 6 3P | AA2: 6kW DC 2xType 6 1P
A3: NBI | B3: 1 | C3: RP | D3: =vlookup(C3,'List of Chargers'!$A$2:$B$5,2,FALSE) -> Roam Point | E3: KE | F3: A | G3: 01 | H3: =CONCATENATE("#",C3,"-",E3,"-",F3,"-",G3,) -> #RP-KE-A-01 | I3: =concatenate("FO-",A3,"-",TEXT(B3,"00"),H3) -> FO-NBI-01#RP-KE-A-01 | J3: Blocked | L3: Anita Karambu | M3: Pangani 1 | N3: =D3&" - "&M3 -> Roam Point - Pangani 1 | O3: =CONCATENATE(I3,": ",N3) -> FO-NBI-01#RP-KE-A-01: Roam Point - Pangani 1 | P3: -1.266212, 36.835316 | Q3: Anita Karambu | R3: 0716899985 | S3: 3BAD8FBE | W3: Roam Electric Limited | X3: Roam Electric Limited | Z3: 1
A4: NBI | B4: 1 | C4: RP | D4: =vlookup(C4,'List of Chargers'!$A$2:$B$5,2,FALSE) -> Roam Point | E4: KE | F4: A | G4: 02 | H4: =CONCATENATE("#",C4,"-",E4,"-",F4,"-",G4,) -> #RP-KE-A-02 | I4: =concatenate("FO-",A4,"-",TEXT(B4,"00"),H4) -> FO-NBI-01#RP-KE-A-02 | J4: Blocked | L4: Edward Kinyua Kimotho | M4: Kariobangi North 1 | N4: =D4&" - "&M4 -> Roam Point - Kariobangi North 1 | O4: =CONCATENATE(I4,": ",N4) -> FO-NBI-01#RP-KE-A-02: Roam Point - Kariobangi North 1 | P4: -1.2564947,36.8817722 | Q4: Edward Kinyua Kimotho | R4: 0790539015 | W4: Roam Electric Limited | X4: Roam Electric Limited | AA4: 1
A5: NBI | B5: 6 | C5: RP | D5: =vlookup(C5,'List of Chargers'!$A$2:$B$5,2,FALSE) -> Roam Point | E5: KE | F5: A | G5: 03 | H5: =CONCATENATE("#",C5,"-",E5,"-",F5,"-",G5,) -> #RP-KE-A-03 | I5: =concatenate("FO-",A5,"-",TEXT(B5,"00"),H5) -> FO-NBI-06#RP-KE-A-03 | J5: Construction | L5: Pheliesia Kasera | M5: Rongai 1 | N5: =D5&" - "&M5 -> Roam Point - Rongai 1 | O5: =CONCATENATE(I5,": ",N5) -> FO-NBI-06#RP-KE-A-03: Roam Point - Rongai 1 | P5: -1.3913462,36.7705494 | Q5: Pheliesia Kasera | R5: 0705797584 | W5: Roam Electric Limited | X5: Roam Electric Limited | AA5: 1
A6: NBI | B6: 5 | C6: RP | D6: =vlookup(C6,'List of Chargers'!$A$2:$B$5,2,FALSE) -> Roam Point | E6: KE | F6: A | G6: 04 | H6: =CONCATENATE("#",C6,"-",E6,"-",F6,"-",G6,) -> #RP-KE-A-04 | I6: =concatenate("FO-",A6,"-",TEXT(B6,"00"),H6) -> FO-NBI-05#RP-KE-A-04 | J6: Blocked | L6: Joyce Pere | M6: Kitengela 1 | N6: =D6&" - "&M6 -> Roam Point - Kitengela 1 | O6: =CONCATENATE(I6,": ",N6) -> FO-NBI-05#RP-KE-A-04: Roam Point - Kitengela 1 | P6: -1.4862217,36.9547761 | Q6: Joyce Pere | R6: 0713226840 | W6: Roam Electric Limited | X6: Roam Electric Limited | AA6: 1
A7: NBI | B7: 1 | C7: RP | D7: =vlookup(C7,'List of Chargers'!$A$2:$B$5,2,FALSE) -> Roam Point | E7: KE | F7: A | G7: 05 | H7: =CONCATENATE("#",C7,"-",E7,"-",F7,"-",G7,) -> #RP-KE-A-05 | I7: =concatenate("FO-",A7,"-",TEXT(B7,"00"),H7) -> FO-NBI-01#RP-KE-A-05 | J7: Construction | L7: Mercy Nduta | M7: Point Mall | N7: =D7&" - "&M7 -> Roam Point - Point Mall | O7: =CONCATENATE(I7,": ",N7) -> FO-NBI-01#RP-KE-A-05: Roam Point - Point Mall | P7: -1.2936642,36.871029 | Q7: Mercy Nduta | R7: 0708534944 | W7: Roam Electric Limited | X7: Roam Electric Limited | AA7: 1
A8: NBI | B8: 1 | C8: RP | D8: =vlookup(C8,'List of Chargers'!$A$2:$B$5,2,FALSE) -> Roam Point | E8: KE | F8: A | G8: 06 | H8: =CONCATENATE("#",C8,"-",E8,"-",F8,"-",G8,) -> #RP-KE-A-06 | I8: =concatenate("FO-",A8,"-",TEXT(B8,"00"),H8) -> FO-NBI-01#RP-KE-A-06 | J8: Archived | L8: John Njoki | M8: Kawangware 1 | N8: =D8&" - "&M8 -> Roam Point - Kawangware 1 | O8: =CONCATENATE(I8,": ",N8) -> FO-NBI-01#RP-KE-A-06: Roam Point - Kawangware 1 | P8: -1.2944176,36.7227883 | Q8: John Njoki | R8: 0727990176 | W8: Roam Electric Limited | X8: Roam Electric Limited | AA8: 1
A9: NBI | B9: 1 | C9: RP | D9: =vlookup(C9,'List of Chargers'!$A$2:$B$5,2,FALSE) -> Roam Point | E9: KE | F9: A | G9: 07 | H9: =CONCATENATE("#",C9,"-",E9,"-",F9,"-",G9,) -> #RP-KE-A-07 | I9: =concatenate("FO-",A9,"-",TEXT(B9,"00"),H9) -> FO-NBI-01#RP-KE-A-07 | J9: Archived | L9: Munene Mbuchi | M9: Ruaka 1 | N9: =D9&" - "&M9 -> Roam Point - Ruaka 1 | O9: =CONCATENATE(I9,": ",N9) -> FO-NBI-01#RP-KE-A-07: Roam Point - Ruaka 1 | P9: -1.207359,36.7856069 | Q9: Munene Mbuchi | R9: 0722531006 | W9: Roam Electric Limited | X9: Roam Electric Limited
A10: NBI | B10: 1 | C10: RP | D10: =vlookup(C10,'List of Chargers'!$A$2:$B$5,2,FALSE) -> Roam Point | E10: KE | F10: A | G10: 08 | H10: =CONCATENATE("#",C10,"-",E10,"-",F10,"-",G10,) -> #RP-KE-A-08 | I10: =concatenate("FO-",A10,"-",TEXT(B10,"00"),H10) -> FO-NBI-01#RP-KE-A-08 | J10: Blocked | L10: Peter Macharia | M10: Kiambu Road 1 | N10: =D10&" - "&M10 -> Roam Point - Kiambu Road 1 | O10: =CONCATENATE(I10,": ",N10) -> FO-NBI-01#RP-KE-A-08: Roam Point - Kiambu Road 1 | P10: -1.2184234,36.8229217 | Q10: Peter Macharia | R10: 0722843770 | W10: Roam Electric Limited | X10: Roam Electric Limited
A11: NBI | B11: 2 | C11: RP | D11: =vlookup(C11,'List of Chargers'!$A$2:$B$5,2,FALSE) -> Roam Point | E11: KE | F11: A | G11: 09 | H11: =CONCATENATE("#",C11,"-",E11,"-",F11,"-",G11,) -> #RP-KE-A-09 | I11: =concatenate("FO-",A11,"-",TEXT(B11,"00"),H11) -> FO-NBI-02#RP-KE-A-09 | J11: Archived | L11: Ivy Cheruto | M11: Juja 1 | N11: =D11&" - "&M11 -> Roam Point - Juja 1 | O11: =CONCATENATE(I11,": ",N11) -> FO-NBI-02#RP-KE-A-09: Roam Point - Juja 1 | P11: -1.0932973,37.0198771 | Q11: Ivy Cheruto | R11: 0700071760 | W11: Roam Electric Limited | X11: Roam Electric Limited
A12: NBI | B12: 1 | C12: RP | D12: =vlookup(C12,'List of Chargers'!$A$2:$B$5,2,FALSE) -> Roam Point | E12: KE | F12: A | G12: 10 | H12: =CONCATENATE("#",C12,"-",E12,"-",F12,"-",G12,) -> #RP-KE-A-10 | I12: =concatenate("FO-",A12,"-",TEXT(B12,"00"),H12) -> FO-NBI-01#RP-KE-A-10 | J12: Archived | L12: George Maina Njoroge | M12: Umoja 1 | N12: =D12&" - "&M12 -> Roam Point - Umoja 1 | O12: =CONCATENATE(I12,": ",N12) -> FO-NBI-01#RP-KE-A-10: Roam Point - Umoja 1 | P12: -1.2785188,36.8879889 | Q12: George Maina Njoroge | R12: 0722958498 | W12: Roam Electric Limited | X12: Roam Electric Limited
A13: NBI | B13: 1 | C13: RP | D13: =vlookup(C13,'List of Chargers'!$A$2:$B$5,2,FALSE) -> Roam Point | E13: KE | F13: A | G13: 11 | H13: =CONCATENATE("#",C13,"-",E13,"-",F13,"-",G13,) -> #RP-KE-A-11 | I13: =concatenate("FO-",A13,"-",TEXT(B13,"00"),H13) -> FO-NBI-01#RP-KE-A-11 | J13: Archived | L13: Kevin Kaburu | M13: Marurui 1 | N13: =D13&" - "&M13 -> Roam Point - Marurui 1 | O13: =CONCATENATE(I13,": ",N13) -> FO-NBI-01#RP-KE-A-11: Roam Point - Marurui 1 | P13: -1.2073934,36.8726554 | Q13: Kevin Kaburu | R13: 0799838826 | W13: Roam Electric Limited | X13: Roam Electric Limited
A14: NBI | B14: 1 | C14: RP | D14: =vlookup(C14,'List of Chargers'!$A$2:$B$5,2,FALSE) -> Roam Point | E14: KE | F14: A | G14: 12 | H14: =CONCATENATE("#",C14,"-",E14,"-",F14,"-",G14,) -> #RP-KE-A-12 | I14: =concatenate("FO-",A14,"-",TEXT(B14,"00"),H14) -> FO-NBI-01#RP-KE-A-12 | J14: Archived | L14: Kevin Njeru | M14: TRM Drive 1 | N14: =D14&" - "&M14 -> Roam Point - TRM Drive 1 | O14: =CONCATENATE(I14,": ",N14) -> FO-NBI-01#RP-KE-A-12: Roam Point - TRM Drive 1 | P14: -1.2188724,36.8848064 | Q14: Kevin Njeru | R14: 0717615283 | W14: Roam Electric Limited | X14: Roam Electric Limited
A15: NBI | B15: 1 | C15: RP | D15: =vlookup(C15,'List of Chargers'!$A$2:$B$5,2,FALSE) -> Roam Point | E15: KE | F15: A | G15: 13 | H15: =CONCATENATE("#",C15,"-",E15,"-",F15,"-",G15,) -> #RP-KE-A-13 | I15: =concatenate("FO-",A15,"-",TEXT(B15,"00"),H15) -> FO-NBI-01#RP-KE-A-13 | J15: Archived | L15: Andrew Murimi | M15: Ngara 1 | N15: =D15&" - "&M15 -> Roam Point - Ngara 1 | O15: =CONCATENATE(I15,": ",N15) -> FO-NBI-01#RP-KE-A-13: Roam Point - Ngara 1 | P15: -1.2736004,36.8319322 | Q15: Andrew Murimi | R15: 0722341329 | W15: Roam Electric Limited | X15: Roam Electric Limited
A16: NBI | B16: 1 | C16: RP | D16: =vlookup(C16,'List of Chargers'!$A$2:$B$5,2,FALSE) -> Roam Point | E16: KE | F16: A | G16: 14 | H16: =CONCATENATE("#",C16,"-",E16,"-",F16,"-",G16,) -> #RP-KE-A-14 | I16: =concatenate("FO-",A16,"-",TEXT(B16,"00"),H16) -> FO-NBI-01#RP-KE-A-14 | J16: Blocked | L16: Stanley Mbugua | M16: Mirema Drive 1 | N16: =D16&" - "&M16 -> Roam Point - Mirema Drive 1 | O16: =CONCATENATE(I16,": ",N16) -> FO-NBI-01#RP-KE-A-14: Roam Point - Mirema Drive 1 | P16: -1.211768, 36.889741 | Q16: Stanley Mbugua | R16: 0702115108 | W16: Roam Electric Limited | X16: Roam Electric Limited
A17: NBI | B17: 1 | C17: RP | D17: =vlookup(C17,'List of Chargers'!$A$2:$B$5,2,FALSE) -> Roam Point | E17: KE | F17: A | G17: 15 | H17: =CONCATENATE("#",C17,"-",E17,"-",F17,"-",G17,) -> #RP-KE-A-15 | I17: =concatenate("FO-",A17,"-",TEXT(B17,"00"),H17) -> FO-NBI-01#RP-KE-A-15 | J17: Blocked | L17: Stanley Mbugua | M17: Alcapone Lounge | N17: =D17&" - "&M17 -> Roam Point - Alcapone Lounge | O17: =CONCATENATE(I17,": ",N17) -> FO-NBI-01#RP-KE-A-15: Roam Point - Alcapone Lounge | P17: -1.231141, 36.876106 | Q17: Stanley Mbugua | R17: 0702115108 | W17: Roam Electric Limited | X17: Roam Electric Limited
A18: NBI | B18: 1 | C18: RP | D18: =vlookup(C18,'List of Chargers'!$A$2:$B$5,2,FALSE) -> Roam Point | E18: KE | F18: A | G18: 16 | H18: =CONCATENATE("#",C18,"-",E18,"-",F18,"-",G18,) -> #RP-KE-A-16 | I18: =concatenate("FO-",A18,"-",TEXT(B18,"00"),H18) -> FO-NBI-01#RP-KE-A-16 | J18: Archived | L18: Andrew Kamanu | M18: Astrol Garden City 1 | N18: =D18&" - "&M18 -> Roam Point - Astrol Garden City 1 | O18: =CONCATENATE(I18,": ",N18) -> FO-NBI-01#RP-KE-A-16: Roam Point - Astrol Garden City 1 | P18: -1.229331, 36.878955 | Q18: Andrew Kamanu | R18: 0723944326 | W18: Roam Electric Limited | X18: Roam Electric Limited
A19: NBI | B19: 1 | C19: RP | D19: =vlookup(C19,'List of Chargers'!$A$2:$B$5,2,FALSE) -> Roam Point | E19: KE | F19: A | G19: 17 | H19: =CONCATENATE("#",C19,"-",E19,"-",F19,"-",G19,) -> #RP-KE-A-17 | I19: =concatenate("FO-",A19,"-",TEXT(B19,"00"),H19) -> FO-NBI-01#RP-KE-A-17 | J19: Blocked | L19: Joyce Wanjiku | M19: Kariobangi Roundabout 1 | N19: =D19&" - "&M19 -> Roam Point - Kariobangi Roundabout 1 | O19: =CONCATENATE(I19,": ",N19) -> FO-NBI-01#RP-KE-A-17: Roam Point - Kariobangi Roundabout 1 | P19: -1.261975, 36.877616 | Q19: Joyce Wanjiku | R19: 0729762478 | W19: Roam Electric Limited | X19: Roam Electric Limited
A20: NBI | B20: 1 | C20: RP | D20: =vlookup(C20,'List of Chargers'!$A$2:$B$5,2,FALSE) -> Roam Point | E20: KE | F20: A | G20: 18 | H20: =CONCATENATE("#",C20,"-",E20,"-",F20,"-",G20,) -> #RP-KE-A-18 | I20: =concatenate("FO-",A20,"-",TEXT(B20,"00"),H20) -> FO-NBI-01#RP-KE-A-18 | J20: Archived | L20: Hans Haerdlte | M20: Kawangware 2 | N20: =D20&" - "&M20 -> Roam Point - Kawangware 2 | O20: =CONCATENATE(I20,": ",N20) -> FO-NBI-01#RP-KE-A-18: Roam Point - Kawangware 2 | P20: -1.2816677,36.7414258 | Q20: Hans Haerdlte | R20: 0113166817 | W20: Roam Electric Limited | X20: Roam Electric Limited
... A25: NBI | B25: 1 | C25: RP | D25: =vlookup(C25,'List of Chargers'!$A$2:$B$5,2,FALSE) -> Roam Point | E25: KE | F25: A | G25: 23 | H25: =CONCATENATE("#",C25,"-",E25,"-",F25,"-",G25,) -> #RP-KE-A-23 | I25: =concatenate("FO-",A25,"-",TEXT(B25,"00"),H25) -> FO-NBI-01#RP-KE-A-23 | J25: Archived | L25: ATLAS; Harrison Wachenje | M25: Mihango 1 | N25: =D25&" - "&M25 -> Roam Point - Mihango 1 | O25: =CONCATENATE(I25,": ",N25) -> FO-NBI-01#RP-KE-A-23: Roam Point - Mihango 1 | P25: -1.2775993,36.949089 | Q25: ATLAS; Harrison Wachenje | R25: 0721715328 | W25: Roam Electric Limited | X25: Roam Electric Limited
A26: NBI | B26: 2 | C26: RP | D26: =vlookup(C26,'List of Chargers'!$A$2:$B$5,2,FALSE) -> Roam Point | E26: KE | F26: A | G26: 24 | H26: =CONCATENATE("#",C26,"-",E26,"-",F26,"-",G26,) -> #RP-KE-A-24 | I26: =concatenate("FO-",A26,"-",TEXT(B26,"00"),H26) -> FO-NBI-02#RP-KE-A-24 | J26: Archived | K26: . | L26: Be Energy; Grace | M26: Ruiru 1 | N26: =D26&" - "&M26 -> Roam Point - Ruiru 1 | O26: =CONCATENATE(I26,": ",N26) -> FO-NBI-02#RP-KE-A-24: Roam Point - Ruiru 1 | P26: -1.146381,36.956178 | Q26: Be Energy; Grace | R26: 0722702811 | W26: Roam Electric Limited | X26: Roam Electric Limited
A27: NBI | B27: 2 | C27: RP | D27: =vlookup(C27,'List of Chargers'!$A$2:$B$5,2,FALSE) -> Roam Point | E27: KE | F27: A | G27: 25 | H27: =CONCATENATE("#",C27,"-",E27,"-",F27,"-",G27,) -> #RP-KE-A-25 | I27: =concatenate("FO-",A27,"-",TEXT(B27,"00"),H27) -> FO-NBI-02#RP-KE-A-25 | J27: Archived | L27: Be Energy; Jespher | M27: Kiambu 1 | N27: =D27&" - "&M27 -> Roam Point - Kiambu 1 | O27: =CONCATENATE(I27,": ",N27) -> FO-NBI-02#RP-KE-A-25: Roam Point - Kiambu 1 | P27: -1.1670501,36.8204359 | Q27: Be Energy; Jespher | R27: 0792887023 | W27: Roam Electric Limited | X27: Roam Electric Limited
A28: NBI | B28: 1 | C28: RP | D28: =vlookup(C28,'List of Chargers'!$A$2:$B$5,2,FALSE) -> Roam Point | E28: KE | F28: A | G28: 26 | H28: =CONCATENATE("#",C28,"-",E28,"-",F28,"-",G28,) -> #RP-KE-A-26 | I28: =concatenate("FO-",A28,"-",TEXT(B28,"00"),H28) -> FO-NBI-01#RP-KE-A-26 | J28: Archived | L28: Be Energy; Antony | M28: Utawala 2 | N28: =D28&" - "&M28 -> Roam Point - Utawala 2 | O28: =CONCATENATE(I28,": ",N28) -> FO-NBI-01#RP-KE-A-26: Roam Point - Utawala 2 | P28: -1.2750468,36.9698007 | Q28: Be Energy; Antony | R28: 0714657138 | W28: Roam Electric Limited | X28: Roam Electric Limited
A29: NBI | B29: 1 | C29: RP | D29: =vlookup(C29,'List of Chargers'!$A$2:$B$5,2,FALSE) -> Roam Point | E29: KE | F29: A | G29: 27 | H29: =CONCATENATE("#",C29,"-",E29,"-",F29,"-",G29,) -> #RP-KE-A-27 | I29: =concatenate("FO-",A29,"-",TEXT(B29,"00"),H29) -> FO-NBI-01#RP-KE-A-27 | J29: Archived | L29: Be Energy; Tabitha | M29: Kayole Junction 1 | N29: =D29&" - "&M29 -> Roam Point - Kayole Junction 1 | O29: =CONCATENATE(I29,": ",N29) -> FO-NBI-01#RP-KE-A-27: Roam Point - Kayole Junction 1 | P29: -1.257151,36.917729 | Q29: Be Energy; Tabitha | R29: 0723332165 | W29: Roam Electric Limited | X29: Roam Electric Limited
A30: NBI | B30: 4 | C30: RP | D30: =vlookup(C30,'List of Chargers'!$A$2:$B$5,2,FALSE) -> Roam Point | E30: KE | F30: A | G30: 28 | H30: =CONCATENATE("#",C30,"-",E30,"-",F30,"-",G30,) -> #RP-KE-A-28 | I30: =concatenate("FO-",A30,"-",TEXT(B30,"00"),H30) -> FO-NBI-04#RP-KE-A-28 | J30: Archived | L30: Be Energy; Philips | M30: Ngong Racecourse 1 | N30: =D30&" - "&M30 -> Roam Point - Ngong Racecourse 1 | O30: =CONCATENATE(I30,": ",N30) -> FO-NBI-04#RP-KE-A-28: Roam Point - Ngong Racecourse 1 | P30: -1.3067629,36.7335908 | Q30: Be Energy; Philips | R30: 0721561395 | W30: Roam Electric Limited | X30: Roam Electric Limited
